Workbook

Sheet pib_mes_tot_2010
A1: Sigla | B1: Codigo | C1: Meso-região | D1: 2002 | E1: 2003 | F1: 2004 | G1: 2005 | H1: 2006 | I1: 2007 | J1: 2008 | K1: 2009 | L1: 2010 | M1: 2011 | N1: 2012 | O1: 2013 | P1: 2014 | Q1: 2015 | R1: 2016 | S1: 2017 | T1: 2018 | U1: 2019 | V1: 2020 | W1: 2021
A2: AC | B2: 1201 | C2: Vale do Juruá | D2: 1005021.4 | E2: 1005897.5 | F2: 1014540.7 | G2: 1092503.3 | H2: 1116065.7 | I2: 1268092.3 | J2: 1395713.5 | K2: 1496288.5 | L2: 1616720.3 | M2: 1521408.2 | N2: 1562338 | O2: 1719504.8 | P2: 1870680.3 | Q2: 1685723.9 | R2: 1734594.3 | S2: 1759701.2 | T2: 1772017 | U2: 1728227.4 | V2: 1737443 | W2: 2081752.8
A3: AC | B3: 1202 | C3: Vale do Acre | D3: 4639695.7 | E3: 4617583.1 | F3: 4832954.3 | G3: 5093570.1 | H3: 5164164.6 | I3: 5640150.1 | J3: 6062801.2 | K3: 6535518.8 | L3: 6725635.3 | M3: 6740731.8 | N3: 7108300.1 | O3: 7408740.4 | P3: 8057536 | Q3: 7656685.8 | R3: 6990877 | S3: 6974170.4 | T3: 7205949.4 | U3: 7053797 | V3: 6957351.6 | W3: 8045352.3
A4: AL | B4: 2701 | C4: Sertão Alagoano | D4: 1688698.9 | E4: 1420907.4 | F4: 1617420.8 | G4: 1711094.5 | H4: 1787765.3 | I4: 1895814.1 | J4: 1957305.2 | K4: 1873822.9 | L4: 1893456.9 | M4: 2084575.1 | N4: 2194443.3 | O4: 2242886 | P4: 2222112.3 | Q4: 2259318.2 | R4: 2184027.2 | S4: 2236623.6 | T4: 2232278.2 | U4: 2333597 | V4: 2415121.4 | W4: 2543769.3
A5: AL | B5: 2702 | C5: Agreste Alagoano | D5: 2988074 | E5: 2668308.8 | F5: 2726389.3 | G5: 2851962.9 | H5: 3011153.2 | I5: 3284011.1 | J5: 3471642.2 | K5: 3652448.1 | L5: 3827720.9 | M5: 3971467 | N5: 4569477.4 | O5: 4594413.3 | P5: 4765856.9 | Q5: 5210777.8 | R5: 4898770.4 | S5: 5117695.6 | T5: 5259699.4 | U5: 5676494.6 | V5: 5901911.5 | W5: 6253577.6
A6: AL | B6: 2703 | C6: Leste Alagoano | D6: 17240315 | E6: 16931236 | F6: 17360067 | G6: 17710301 | H6: 18635947 | I6: 19970631 | J6: 20473869 | K6: 20693081 | L6: 21411860 | M6: 23170077 | N6: 22871440 | O6: 22823337 | P6: 23238477 | Q6: 24328170 | R6: 24299385 | S6: 24986211 | T6: 24372518 | U6: 25119807 | V6: 25035663 | W6: 27336931
A7: AM | B7: 1301 | C7: Norte Amazonense | D7: 328010.64 | E7: 329017.22 | F7: 342594.33 | G7: 350902.36 | H7: 380063.09 | I7: 409067.08 | J7: 449804.46 | K7: 470952.93 | L7: 493112.2 | M7: 538009.16 | N7: 516916.1 | O7: 553740.37 | P7: 602520.89 | Q7: 598772.82 | R7: 568568.24 | S7: 578695.36 | T7: 566601.66 | U7: 600316.13 | V7: 595643.27 | W7: 617379.56
A8: AM | B8: 1302 | C8: Sudoeste Amazonense | D8: 1183021.2 | E8: 1128364.7 | F8: 1112310.8 | G8: 1147695.3 | H8: 1273660.9 | I8: 1211351.8 | J8: 1263630.6 | K8: 1318052.9 | L8: 1482611.7 | M8: 1692188.7 | N8: 1747445.4 | O8: 1957346.7 | P8: 2006958.9 | Q8: 1940329.7 | R8: 1896084.5 | S8: 1959420.9 | T8: 2053067 | U8: 2098369.3 | V8: 2114947.2 | W8: 2140794.1
A9: AM | B9: 1303 | C9: Centro Amazonense | D9: 39523816 | E9: 40712878 | F9: 45676033 | G9: 46389879 | H9: 50917620 | I9: 52211228 | J9: 53042225 | K9: 51787398 | L9: 57525612 | M9: 61393001 | N9: 57842010 | O9: 61762079 | P9: 59449999 | Q9: 54995543 | R9: 52227088 | S9: 52571912 | T9: 54079178 | U9: 56117786 | V9: 56501263 | W9: 57556148
A10: AM | B10: 1304 | C10: Sul Amazonense | D10: 936877.98 | E10: 893146.52 | F10: 914136.97 | G10: 990542.56 | H10: 1225343.2 | I10: 1199379.6 | J10: 1227826.8 | K10: 1242262.1 | L10: 1375786.4 | M10: 1678980.5 | N10: 1680466.5 | O10: 1799400.7 | P10: 1874273.2 | Q10: 1833129.7 | R10: 1793681.6 | S10: 1945343.8 | T10: 1925512.5 | U10: 1967143.7 | V10: 2012942.9 | W10: 2004439.9
A11: AP | B11: 1601 | C11: Norte do Amapá | D11: 303495.74 | E11: 300548.6 | F11: 331412.12 | G11: 361010.93 | H11: 390635.35 | I11: 465618.94 | J11: 497532.66 | K11: 516840.76 | L11: 493286 | M11: 529451.7 | N11: 573709.67 | O11: 650597.54 | P11: 585027.99 | Q11: 545926.19 | R11: 561166.19 | S11: 595614.29 | T11: 597116.31 | U11: 610301.11 | V11: 607041.87 | W11: 577785.67
A12: AP | B12: 1602 | C12: Sul do Amapá | D12: 5725048.6 | E12: 5382811.1 | F12: 5579034.9 | G12: 5833446.9 | H12: 6723511.2 | I12: 7144248.3 | J12: 7589471.8 | K12: 7604778.1 | L12: 7744509.4 | M12: 8157171.6 | N12: 8946160.4 | O12: 9503571.9 | P12: 9300097.4 | Q12: 8960039 | R12: 8537256.4 | S12: 8878048.2 | T12: 9238222.8 | U12: 9220532.9 | V12: 9139347.3 | W12: 8945425.1
A13: BA | B13: 2901 | C13: Extremo Oeste Baiano | D13: 6179244.3 | E13: 7018812.8 | F13: 8887933.1 | G13: 7602538.9 | H13: 6659216.4 | I13: 8330178.6 | J13: 9308099.1 | K13: 8798591.9 | L13: 7766683.2 | M13: 9433740.4 | N13: 11345783 | O13: 10477641 | P13: 11382295 | Q13: 11783858 | R13: 9196412.6 | S13: 10897237 | T13: 13900310 | U13: 11824855 | V13: 15744499 | W13: 17268848
... A138: TO | B138: 1702 | C138: Oriental do Tocantins | D138: 4041951.8 | E138: 4095113.1 | F138: 4169939.4 | G138: 4271359.9 | H138: 4556924.3 | I138: 4972905.2 | J138: 5585027.5 | K138: 5983244.1 | L138: 6865669.3 | M138: 7187136.7 | N138: 7566703.3 | O138: 8104715.7 | P138: 8675556 | Q138: 8688457.3 | R138: 8595237.3 | S138: 9053757.4 | T138: 9189103.5 | U138: 9714360.8 | V138: 9959137.2 | W138: 10469800

Sheet pop_state
A1: Sigla | B1: Codigo | C1: Estado | D1: 1872 | E1: 1890 | F1: 1900 | G1: 1910 | H1: 1920 | I1: 1940 | J1: 1950 | K1: 1960 | L1: 1970 | M1: 1980 | N1: 1991 | O1: 1996 | P1: 2000 | Q1: 2007 | R1: 2010 | S1: 2022
A2: AC | B2: 12 | C2: Acre | G2: 74484 | H2: 92379 | I2: 79768 | J2: 114755 | K2: 158852 | L2: 215299 | M2: 301276 | N2: 417718 | O2: 483593 | P2: 557882 | Q2: 655385 | R2: 733559 | S2: 830018
A3: AL | B3: 27 | C3: Alagoas | D3: 338854 | E3: 511440 | F3: 649273 | G3: 814060 | H3: 978748 | I3: 951300 | J3: 1093137 | K3: 1256159 | L3: 1588068 | M3: 1982915 | N3: 2514100 | O3: 2633251 | P3: 2827856 | Q3: 3037103 | R3: 3120494 | S3: 3127683
A4: AM | B4: 13 | C4: Amazonas | D4: 57610 | E4: 144458 | F4: 249756 | G4: 335543 | H4: 348947 | I4: 416159 | J4: 514099 | K4: 714774 | L4: 955203 | M4: 1430528 | N4: 2103243 | O4: 2389279 | P4: 2817252 | Q4: 3221939 | R4: 3483985 | S4: 3941613
A5: AP | B5: 16 | C5: Amapá | D5: 3148 | E5: 10348 | G5: 31396 | H5: 36477 | I5: 30747 | J5: 37477 | K5: 68520 | L5: 114230 | M5: 175258 | N5: 289397 | O5: 379459 | P5: 477032 | Q5: 587311 | R5: 669526 | S5: 733759
A6: BA | B6: 29 | C6: Bahia | D6: 1379616 | E6: 1919802 | F6: 2117956 | G6: 2626989 | H6: 3334465 | I6: 3918112 | J6: 4834575 | K6: 5919052 | L6: 7493437 | M6: 9455392 | N6: 11867991 | O6: 12541675 | P6: 13085769 | Q6: 14080654 | R6: 14016906 | S6: 14141626
A7: CE | B7: 23 | C7: Ceará | D7: 742819 | E7: 805687 | F7: 849127 | G7: 1119489 | H7: 1319228 | I7: 2091032 | J7: 2695450 | K7: 3289595 | L7: 4361603 | M7: 5288429 | N7: 6366647 | O7: 6809290 | P7: 7431597 | Q7: 8185286 | R7: 8452381 | S7: 8794957
A8: DF | B8: 53 | C8: Distrito Federal | K8: 139796 | L8: 537492 | M8: 1176908 | N8: 1601094 | O8: 1821946 | P8: 2051146 | Q8: 2455903 | R8: 2570160 | S8: 2817381
A9: ES | B9: 32 | C9: Espírito Santo | D9: 82137 | E9: 135997 | F9: 209783 | G9: 340805 | H9: 457328 | I9: 790149 | J9: 957238 | K9: 1418348 | L9: 1599324 | M9: 2023338 | N9: 2600618 | O9: 2802707 | P9: 3097498 | Q9: 3351669 | R9: 3514952 | S9: 3833712
A10: GO | B10: 52 | C10: Goiás | D10: 122796 | E10: 172420 | F10: 255284 | G10: 318159 | H10: 400022 | I10: 662018 | J10: 1010881 | K10: 1593788 | L10: 2938029 | M10: 3860174 | N10: 4018903 | O10: 4514967 | P10: 5004197 | Q10: 5647035 | R10: 6003788 | S10: 7056495
A11: MA | B11: 21 | C11: Maranhão | D11: 359040 | E11: 430854 | F11: 499308 | G11: 657453 | H11: 874337 | I11: 1235169 | J11: 1583248 | K11: 2477371 | L11: 2992678 | M11: 3996444 | N11: 4930253 | O11: 5222183 | P11: 5657552 | Q11: 6118995 | R11: 6574789 | S11: 6776699
A12: MG | B12: 31 | C12: Minas Gerais | D12: 2039735 | E12: 3184099 | F12: 3594471 | G12: 4479689 | H12: 5888173 | I12: 6763368 | J12: 7782188 | K12: 9960040 | L12: 11485663 | M12: 13380105 | N12: 15743152 | O12: 16672613 | P12: 17905134 | Q12: 19273506 | R12: 19597330 | S12: 20539989
A13: MS | B13: 50 | C13: Mato Grosso do Sul | D13: 10447 | E13: 26304 | G13: 71678 | H13: 130384 | I13: 238640 | J13: 309395 | K13: 572018 | L13: 0 | M13: 1369769 | N13: 1780373 | O13: 1927834 | P13: 2078070 | Q13: 2265274 | R13: 2449024 | S13: 2757013
A14: MT | B14: 51 | C14: Mato Grosso | D14: 49970 | E14: 66523 | F14: 118025 | G14: 114204 | H14: 98228 | I14: 187524 | J14: 212649 | K14: 324845 | L14: 1597009 | M14: 1138918 | N14: 2027231 | O14: 2235832 | P14: 2505245 | Q14: 2854642 | R14: 3035122 | S14: 3658649
A15: PA | B15: 15 | C15: Pará | D15: 272089 | E15: 318107 | F15: 445356 | G15: 752449 | H15: 947030 | I15: 913897 | J15: 1123273 | K15: 1538193 | L15: 2166998 | M15: 3403498 | N15: 4950060 | O15: 5510849 | P15: 6195965 | Q15: 7065573 | R15: 7581051 | S15: 8120131
A16: PB | B16: 25 | C16: Paraíba | D16: 376226 | E16: 457232 | F16: 490784 | G16: 604985 | H16: 961106 | I16: 1422282 | J16: 1713259 | K16: 1991145 | L16: 2382463 | M16: 2770346 | N16: 3201114 | O16: 3305616 | P16: 3444794 | Q16: 3641395 | R16: 3766528 | S16: 3974687
A17: PE | B17: 26 | C17: Pernambuco | D17: 834314 | E17: 1030224 | F17: 1178150 | G17: 1570183 | H17: 2154835 | I17: 2688240 | J17: 3395766 | K17: 4081947 | L17: 5161866 | M17: 6143503 | N17: 7127855 | O17: 7399071 | P17: 7929154 | Q17: 8485386 | R17: 8796448 | S17: 9058931
A18: PI | B18: 22 | C18: Piauí | D18: 181089 | E18: 267609 | F18: 334328 | G18: 428216 | H18: 609003 | I18: 817601 | J18: 1045696 | K18: 1249200 | L18: 1680573 | M18: 2139196 | N18: 2582137 | O18: 2673085 | P18: 2843428 | Q18: 3032421 | R18: 3118360 | S18: 3271199
A19: PR | B19: 41 | C19: Paraná | D19: 126722 | E19: 249491 | F19: 327136 | G19: 511770 | H19: 685711 | I19: 1236276 | J19: 2115547 | K19: 4263721 | L19: 6929821 | M19: 7629849 | N19: 8448713 | O19: 9003804 | P19: 9564643 | Q19: 10284503 | R19: 10444526 | S19: 11444380
A20: RJ | B20: 33 | C20: Rio de Janeiro | D20: 1057696 | E20: 1399535 | F20: 1737478 | G20: 2136956 | H20: 2706970 | I20: 3611998 | J20: 4674645 | K20: 6649646 | L20: 8994802 | M20: 11291631 | N20: 12807706 | O20: 13406308 | P20: 14392106 | Q20: 15420375 | R20: 15989929 | S20: 16055174
A21: RN | B21: 24 | C21: Rio Grande do Norte | D21: 233979 | E21: 268273 | F21: 274317 | G21: 398644 | H21: 537135 | I21: 768018 | J21: 967921 | K21: 1140823 | L21: 1550184 | M21: 1898835 | N21: 2415567 | O21: 2558660 | P21: 2777509 | Q21: 3013740 | R21: 3168027 | S21: 3302729
A22: RO | B22: 11 | C22: Rondônia | H22: 23305 | I22: 14417 | J22: 36935 | K22: 70232 | L22: 111064 | M22: 491025 | N22: 1132692 | O22: 1229306 | P22: 1380952 | Q22: 1453756 | R22: 1562409 | S22: 1581196
A23: RR | B23: 14 | C23: Roraima | E23: 3457 | G23: 23152 | H23: 8914 | I23: 13533 | J23: 18116 | K23: 28871 | L23: 40885 | M23: 79121 | N23: 217583 | O23: 247131 | P23: 324397 | Q23: 395725 | R23: 450479 | S23: 636707
A24: RS | B24: 43 | C24: Rio Grande do Sul | D24: 434813 | E24: 897455 | F24: 1149070 | G24: 1594439 | H24: 2182194 | I24: 3320689 | J24: 4164821 | K24: 5388659 | L24: 6664841 | M24: 7773849 | N24: 9138670 | O24: 9634688 | P24: 10187842 | Q24: 10582840 | R24: 10693929 | S24: 10882965
A25: SC | B25: 42 | C25: Santa Catarina | D25: 159802 | E25: 283769 | F25: 320289 | G25: 450227 | H25: 668743 | I25: 1178340 | J25: 1560502 | K25: 2129252 | L25: 2901660 | M25: 3628292 | N25: 4541994 | O25: 4875244 | P25: 5357864 | Q25: 5866252 | R25: 6248436 | S25: 7610361
A26: SE | B26: 28 | C26: Sergipe | D26: 176243 | E26: 310926 | F26: 356264 | G26: 409931 | H26: 477064 | I26: 542326 | J26: 644361 | K26: 751778 | L26: 900679 | M26: 1140379 | N26: 1491876 | O26: 1624020 | P26: 1784829 | Q26: 1939426 | R26: 2068017 | S26: 2210004
A27: SP | B27: 35 | C27: São Paulo | D27: 837354 | E27: 1384753 | F27: 2282279 | G27: 3455030 | H27: 4592188 | I27: 7180316 | J27: 9134423 | K27: 12823806 | L27: 17770975 | M27: 25042074 | N27: 31588925 | O27: 34119110 | P27: 37035456 | Q27: 39827570 | R27: 41262199 | S27: 44411238
A28: TO | B28: 17 | C28: Tocantins | D28: 37599 | E28: 55152 | G28: 89246 | H28: 111897 | I28: 164396 | J28: 204041 | K28: 323672 | L28: 0 | M28: 0 | N28: 919863 | O28: 1048642 | P28: 1157690 | Q28: 1243627 | R28: 1383445 | S28: 1511460

Sheet pib_2010_state
A1: Sigla | B1: Codigo | C1: Estado | D1: 1939 | E1: 1947 | F1: 1948 | G1: 1949 | H1: 1950 | I1: 1951 | J1: 1952 | K1: 1953 | L1: 1954 | M1: 1955 | N1: 1956 | O1: 1957 | P1: 1958 | Q1: 1959 | R1: 1960 | S1: 1961 | T1: 1962 | U1: 1963 | V1: 1964 | W1: 1965 | X1: 1966 | Y1: 1967 | Z1: 1968 | AA1: 1969 | AB1: 1970 | AC1: 1975 | AD1: 1980 | AE1: 1985 | AF1: 1986 | AG1: 1987 | AH1: 1988 | AI1: 1989 | AJ1: 1990 | AK1: 1991 | AL1: 1992 | AM1: 1993 | AN1: 1994 | AO1: 1995 | AP1: 1996 | AQ1: 1997 | AR1: 1998 | AS1: 1999 | AT1: 2000 | AU1: 2001 | AV1: 2002 | AW1: 2003 | AX1: 2004 | AY1: 2005 | AZ1: 2006 | BA1: 2007 | BB1: 2008 | BC1: 2009 | BD1: 2010 | BE1: 2011 | BF1: 2012 | BG1: 2013 | BH1: 2014 | BI1: 2015 | BJ1: 2016 | BK1: 2017 | BL1: 2018 | BM1: 2019 | BN1: 2020 | BO1: 2021 | BP1: 2022 | BQ1: 2023
A2: AC | B2: 12 | C2: Acre | AB2: 1002208.9 | AC2: 963996.13 | AD2: 2093731.4 | AE2: 2486977 | AF2: 2850661.1 | AG2: 2729036.6 | AH2: 2806751.9 | AI2: 2815572.6 | AJ2: 2898594.5 | AK2: 2834006.2 | AL2: 3044683.9 | AM2: 3146717.2 | AN2: 3667377.6 | AO2: 4265243.7 | AP2: 4248441.5 | AQ2: 4202091.5 | AR2: 4362855.5 | AS2: 4449846.6 | AT2: 4863191.7 | AU2: 5162919 | AV2: 5644716.6 | AW2: 5623480.3 | AX2: 5847495.7 | AY2: 6186073 | AZ2: 6280230.3 | BA2: 6908242.2 | BB2: 7458515.1 | BC2: 8031806.8 | BD2: 8342356 | BE2: 8262140.2 | BF2: 8670638.3 | BG2: 9128245 | BH2: 9928216.6 | BI2: 9342409.8 | BJ2: 8725471.3 | BK2: 8733872.9 | BL2: 8977965.8 | BM2: 8782023.8 | BN2: 8694793.5 | BO2: 9977503.5 | BP2: 10179759 | BQ2: 10749557
A3: AL | B3: 27 | C3: Alagoas | D3: 1065466.7 | E3: 1604315.3 | F3: 1694613 | G3: 1798286.4 | H3: 1790502.2 | I3: 1901336.5 | J3: 1893912.8 | K3: 1885108.9 | L3: 1932123.3 | M3: 1997566.9 | N3: 2309073.3 | O3: 2646150.8 | P3: 3045008.7 | Q3: 3219890.8 | R3: 3462799.7 | S3: 3836398.9 | T3: 4078016.9 | U3: 4210969.3 | V3: 4269676.2 | W3: 4238181 | X3: 4162834.6 | Y3: 1329540.6 | Z3: 1412591.1 | AA3: 1550232.7 | AB3: 5315583.3 | AC3: 7917356.5 | AD3: 11885468 | AE3: 16339942 | AF3: 16152668 | AG3: 17656896 | AH3: 14490757 | AI3: 12637480 | AJ3: 14786576 | AK3: 15041856 | AL3: 15192301 | AM3: 14628035 | AN3: 15959446 | AO3: 16054667 | AP3: 15627525 | AQ3: 16790818 | AR3: 17191397 | AS3: 16533266 | AT3: 17537581 | AU3: 17705297 | AV3: 21917088 | AW3: 21020451 | AX3: 21703876 | AY3: 22273357 | AZ3: 23434866 | BA3: 25150457 | BB3: 25902817 | BC3: 26219352 | BD3: 27133038 | BE3: 29226119 | BF3: 29635360 | BG3: 29660636 | BH3: 30226446 | BI3: 31798266 | BJ3: 31382183 | BK3: 32340532 | BL3: 31864494 | BM3: 33129898 | BN3: 33352695 | BO3: 35600488 | BP3: 32705149 | BQ3: 36670514
A4: AM | B4: 13 | C4: Amazonas | D4: 1306972.5 | E4: 1707321 | F4: 1534147.5 | G4: 1573781.2 | H4: 1510285.5 | I4: 1732135 | J4: 1814336.7 | K4: 1717543.6 | L4: 1800387.6 | M4: 1909004.8 | N4: 2533566.5 | O4: 2909343.3 | P4: 2975372.3 | Q4: 3117376.2 | R4: 3656003.1 | S4: 4719598.7 | T4: 3820844.7 | U4: 3552040.1 | V4: 3699299.7 | W4: 3896392.2 | X4: 3840710.5 | Y4: 1122862.1 | Z4: 1311776.4 | AA4: 1515542.2 | AB4: 5382028.1 | AC4: 9341818.2 | AD4: 19874706 | AE4: 29035793 | AF4: 36136776 | AG4: 38250948 | AH4: 38871490 | AI4: 38667541 | AJ4: 38060879 | AK4: 35610229 | AL4: 33260302 | AM4: 41763275 | AN4: 39314772 | AO4: 34717201 | AP4: 36368043 | AQ4: 33967417 | AR4: 33985845 | AS4: 33218538 | AT4: 37811752 | AU4: 37651010 | AV4: 41971726 | AW4: 43063406 | AX4: 48045076 | AY4: 48879020 | AZ4: 53796688 | BA4: 55031026 | BB4: 55983487 | BC4: 54818666 | BD4: 60877123 | BE4: 65302179 | BF4: 61786838 | BG4: 66072567 | BH4: 63933753 | BI4: 59367775 | BJ4: 56485423 | BK4: 57055373 | BL4: 58624361 | BM4: 60783614 | BN4: 61224796 | BO4: 61398165 | BP4: 62404395 | BQ4: 66152030
A5: AP | B5: 16 | C5: Amapá | AB5: 875963.83 | AC5: 745357.83 | AD5: 1464037.8 | AE5: 2300008.1 | AF5: 2346588 | AG5: 2484644 | AH5: 2901533.4 | AI5: 3931050.3 | AJ5: 3368817.8 | AK5: 3398740.3 | AL5: 3693589.3 | AM5: 3607236.7 | AN5: 4177172.4 | AO5: 5194339.4 | AP5: 5295658.3 | AQ5: 5484742.1 | AR5: 5248631.5 | AS5: 5073895 | AT5: 5320892.5 | AU5: 5844493.4 | AV5: 6028545 | AW5: 5683359.4 | AX5: 5910447.4 | AY5: 6194457.6 | AZ5: 7114146.6 | BA5: 7609867.4 | BB5: 8087004.3 | BC5: 8121619.3 | BD5: 8237795 | BE5: 8686623.2 | BF5: 9519870.3 | BG5: 10154169 | BH5: 9885125.7 | BI5: 9505965 | BJ5: 9098422.5 | BK5: 9473661.8 | BL5: 9835339.1 | BM5: 9830833.5 | BN5: 9746390.3 | BO5: 9382530.2 | BP5: 10153168 | BQ5: 11456399
A6: BA | B6: 29 | C6: Bahia | D6: 5391261.6 | E6: 7261908.5 | F6: 7464077.4 | G6: 7476022.2 | H6: 7973812.8 | I6: 7954215 | J6: 8148599.7 | K6: 8922848.6 | L6: 10637656 | M6: 11021059 | N6: 11304838 | O6: 12519423 | P6: 14433721 | Q6: 16402338 | R6: 18205707 | S6: 17443195 | T6: 18351076 | U6: 17296891 | V6: 20261950 | W6: 21840304 | X6: 23168157 | Y6: 7725636.2 | Z6: 8201752.1 | AA6: 8948070.5 | AB6: 29789415 | AC6: 46709091 | AD6: 77765199 | AE6: 1.0202433e+08 | AF6: 1.0541927e+08 | AG6: 99847456 | AH6: 1.0140606e+08 | AI6: 98809706 | AJ6: 94041247 | AK6: 93022852 | AL6: 92233089 | AM6: 95645785 | AN6: 1.0013498e+08 | AO6: 91115563 | AP6: 94393187 | AQ6: 98690775 | AR6: 97432265 | AS6: 99849597 | AT6: 1.0502387e+08 | AU6: 1.0658013e+08 | AV6: 1.117867e+08 | AW6: 1.1185276e+08 | AX6: 1.2042946e+08 | AY6: 1.2700145e+08 | AZ6: 1.2844937e+08 | BA6: 1.3837506e+08 | BB6: 1.4156356e+08 | BC6: 1.4956184e+08 | BD6: 154419547 | BE6: 1.5380814e+08 | BF6: 1.5614836e+08 | BG6: 1.6296672e+08 | BH6: 1.6518873e+08 | BI6: 1.6804902e+08 | BJ6: 1.6413989e+08 | BK6: 1.6443717e+08 | BL6: 1.67623e+08 | BM6: 1.6476278e+08 | BN6: 1.6112173e+08 | BO6: 1.6460061e+08 | BP6: 1.7312138e+08 | BQ6: 1.7621512e+08
A7: CE | B7: 23 | C7: Ceará | D7: 2507398.4 | E7: 3090173.8 | F7: 3330875 | G7: 3659434.3 | H7: 4409291.8 | I7: 3506134.2 | J7: 4185706.5 | K7: 3728326.4 | L7: 3985004.3 | M7: 4398583.3 | N7: 5203432.5 | O7: 5761780.1 | P7: 4083223.7 | Q7: 7222620.5 | R7: 8434072.2 | S7: 8831997.5 | T7: 10580801 | U7: 10398726 | V7: 11407532 | W7: 11791713 | X7: 11249565 | Y7: 3918198.7 | Z7: 4186416.6 | AA7: 4280789.6 | AB7: 11295614 | AC7: 16331618 | AD7: 27667165 | AE7: 32839080 | AF7: 35633051 | AG7: 33941846 | AH7: 34234105 | AI7: 33695187 | AJ7: 33888590 | AK7: 38711049 | AL7: 38551063 | AM7: 40221693 | AN7: 44033244 | AO7: 47373401 | AP7: 49915142 | AQ7: 50084578 | AR7: 49490908 | AS7: 49429157 | AT7: 51034492 | AU7: 51172498 | AV7: 54558495 | AW7: 54428283 | AX7: 57008117 | AY7: 59061046 | AZ7: 62643676 | BA7: 64319745 | BB7: 70295249 | BC7: 72860438 | BD7: 79336299 | BE7: 82807417 | BF7: 82938505 | BG7: 86745553 | BH7: 92987903 | BI7: 89584916 | BJ7: 87813047 | BK7: 90515884 | BL7: 91297891 | BM7: 91907924 | BN7: 88082954 | BO7: 90971450 | BP7: 91839452 | BQ7: 94954113
A8: DF | B8: 53 | C8: Distrito Federal | D8: 0 | E8: 0 | M8: 0 | R8: 50403.097 | S8: 580915.14 | T8: 1053050.1 | U8: 551390.49 | V8: 725287.69 | W8: 572684.54 | X8: 545675.82 | Y8: 679532.65 | Z8: 746405.42 | AA8: 864917.61 | AB8: 9889199.7 | AC8: 17358556 | AD8: 35931894 | AE8: 26046898 | AF8: 30056829 | AG8: 29885030 | AH8: 30284006 | AI8: 33681923 | AJ8: 33712955 | AK8: 48960095 | AL8: 42576560 | AM8: 42638012 | AN8: 45330958 | AO8: 1.073403e+08 | AP8: 1.1251419e+08 | AQ8: 1.1833935e+08 | AR8: 1.2176185e+08 | AS8: 1.159084e+08 | AT8: 1.0491479e+08 | AU8: 1.0747188e+08 | AV8: 1.0240048e+08 | AW8: 97336121 | AX8: 1.0365467e+08 | AY8: 1.0893595e+08 | AZ8: 1.1405301e+08 | BA8: 1.182186e+08 | BB8: 1.2833669e+08 | BC8: 1.3479596e+08 | BD8: 144174102 | BE8: 1.4269845e+08 | BF8: 1.4035055e+08 | BG8: 1.3994505e+08 | BH8: 1.4564174e+08 | BI8: 1.4786559e+08 | BJ8: 1.4942286e+08 | BK8: 1.4975001e+08 | BL8: 1.4922195e+08 | BM8: 1.5373509e+08 | BN8: 1.4029107e+08 | BO8: 1.3394422e+08 | BP8: 1.4136591e+08 | BQ8: 1.4950868e+08
A9: ES | B9: 32 | C9: Espírito Santo | D9: 1427725.4 | E9: 1939084.1 | F9: 2037425.7 | G9: 2783864.1 | H9: 2760958.4 | I9: 3715455.7 | J9: 2832911.6 | K9: 3141848.1 | L9: 3282414 | M9: 3473601.6 | N9: 3455592.3 | O9: 3883866.6 | P9: 3855322.9 | Q9: 4175140.6 | R9: 4495694.9 | S9: 4139998.8 | T9: 4684208.6 | U9: 4818419.6 | V9: 6735876 | W9: 6049661.6 | X9: 6541597.3 | Y9: 2059336 | Z9: 2503475.9 | AA9: 2351063.8 | AB9: 9202603.6 | AC9: 13118298 | AD9: 26368422 | AE9: 32732893 | AF9: 36114069 | AG9: 31171834 | AH9: 32159127 | AI9: 37189842 | AJ9: 34702934 | AK9: 35022597 | AL9: 35440845 | AM9: 36381169 | AN9: 42598170 | AO9: 48472740 | AP9: 46592408 | AQ9: 47913091 | AR9: 47364815 | AS9: 47305750 | AT9: 52482545 | AU9: 50757224 | AV9: 51386218 | AW9: 52482911 | AX9: 61399642 | AY9: 67635696 | AZ9: 72024733 | BA9: 76773485 | BB9: 83880124 | BC9: 75045605 | BD9: 85310285 | BE9: 97837518 | BF9: 99938511 | BG9: 93299242 | BH9: 95001260 | BI9: 82546036 | BJ9: 69315613 | BK9: 69391489 | BL9: 80239482 | BM9: 77170248 | BN9: 73059699 | BO9: 86981139 | BP9: 78488340 | BQ9: 85791680
A10: GO | B10: 52 | C10: Goiás | D10: 1413519.2 | E10: 1565688.1 | F10: 1750532.8 | G10: 1917274.2 | H10: 2472500.1 | I10: 3052604.4 | J10: 2530522.2 | K10: 3602652.5 | L10: 3578819.3 | M10: 4300181 | N10: 4273389.1 | O10: 4225305.4 | P10: 5064463.5 | Q10: 6011084.1 | R10: 6056184 | S10: 7369197.9 | T10: 9313308.9 | U10: 9420628 | V10: 10375422 | W10: 10356200 | X10: 10456644 | Y10: 3500875.7 | Z10: 3728690.6 | AA10: 3593468.6 | AB10: 11849321 | AC10: 19279923 | AD10: 30658210 | AE10: 34408604 | AF10: 41374541 | AG10: 37355798 | AH10: 36949500 | AI10: 31800192 | AJ10: 36677377 | AK10: 39836843 | AL10: 36743146 | AM10: 40265750 | AN10: 45546528 | AO10: 49859820 | AP10: 51583453 | AQ10: 53562920 | AR10: 54383821 | AS10: 52904283 | AT10: 59255901 | AU10: 62397449 | AV10: 73385973 | AW10: 75859087 | AX10: 78971749 | AY10: 77481048 | AZ10: 82682888 | BA10: 90382183 | BB10: 95895193 | BC10: 1.0068814e+08 | BD10: 106770109 | BE10: 1.1198144e+08 | BF10: 1.1867507e+08 | BG10: 1.2036896e+08 | BH10: 1.2172855e+08 | BI10: 1.1907576e+08 | BJ10: 1.153054e+08 | BK10: 1.1745667e+08 | BL10: 1.1459199e+08 | BM10: 1.1724663e+08 | BN10: 1.1827424e+08 | BO10: 1.2586122e+08 | BP10: 1.3697886e+08 | BQ10: 1.3768348e+08
A11: MA | B11: 21 | C11: Maranhão | D11: 1470344.1 | E11: 1326199.6 | F11: 1526853.6 | G11: 1391932.1 | H11: 1658635.5 | I11: 1796675.8 | J11: 2005319.5 | K11: 2220239.3 | L11: 2360264.3 | M11: 2469898 | N11: 2541584.1 | O11: 2752850.5 | P11: 3317223.6 | Q11: 4161161.3 | R11: 4755776.4 | S11: 4995598.6 | T11: 5988439.2 | U11: 5477348.8 | V11: 5595122.8 | W11: 5742051.6 | X11: 6070800.5 | Y11: 2042467.7 | Z11: 2073769.8 | AA11: 2093922.8 | AB11: 6445144.7 | AC11: 9209310.1 | AD11: 15191359 | AE11: 14155251 | AF11: 16484601 | AG11: 15182045 | AH11: 16386699 | AI11: 17001626 | AJ11: 16698332 | AK11: 17201064 | AL11: 16950697 | AM11: 17191705 | AN11: 19136987 | AO11: 22031808 | AP11: 24688840 | AQ11: 24990047 | AR11: 24154596 | AS11: 24574936 | AT11: 26883785 | AU11: 27991864 | AV11: 30251558 | AW11: 32474556 | AX11: 34193501 | AY11: 36110579 | AZ11: 40025184 | BA11: 38895122 | BB11: 44135435 | BC11: 44447682 | BD11: 46309633 | BE11: 48139044 | BF11: 51735228 | BG11: 53855578 | BH11: 56684851 | BI11: 53818216 | BJ11: 54119332 | BK11: 54792846 | BL11: 57494298 | BM11: 54692305 | BN11: 56420932 | BO11: 58340503 | BP11: 60103549 | BQ11: 61013526
A12: MG | B12: 31 | C12: Minas Gerais | D12: 12004258 | E12: 19107575 | F12: 21200898 | G12: 21260640 | H12: 22252501 | I12: 23897532 | J12: 24350308 | K12: 27229350 | L12: 28762290 | M12: 29815900 | N12: 31108348 | O12: 33930483 | P12: 35704468 | Q12: 39002151 | R12: 42727679 | S12: 46091987 | T12: 51618142 | U12: 46330958 | V12: 53452435 | W12: 54344417 | X12: 59221278 | Y12: 18671796 | Z12: 19489576 | AA12: 21139920 | AB12: 64783671 | AC12: 1.0666899e+08 | AD12: 1.6913729e+08 | AE12: 1.8333101e+08 | AF12: 1.9410627e+08 | AG12: 2.0890904e+08 | AH12: 2.0495774e+08 | AI12: 2.0945066e+08 | AJ12: 1.9450315e+08 | AK12: 2.0129427e+08 | AL12: 2.0067065e+08 | AM12: 2.0803464e+08 | AN12: 2.3241136e+08 | AO12: 2.1007324e+08 | AP12: 2.1582596e+08 | AQ12: 2.2371113e+08 | AR12: 2.1610354e+08 | AS12: 2.1405931e+08 | AT12: 2.2712732e+08 | AU12: 2.3219092e+08 | AV12: 2.3570348e+08 | AW12: 2.4009131e+08 | AX12: 2.655956e+08 | AY12: 2.7094854e+08 | AZ12: 2.8648782e+08 | BA12: 3.0421031e+08 | BB12: 3.2416793e+08 | BC12: 3.1165622e+08 | BD12: 351123418 | BE12: 3.6939613e+08 | BF12: 3.7827016e+08 | BG12: 3.8823911e+08 | BH12: 3.8111072e+08 | BI12: 3.5615324e+08 | BJ12: 3.456191e+08 | BK12: 3.5269471e+08 | BL12: 3.6007369e+08 | BM12: 3.6626713e+08 | BN12: 3.6031504e+08 | BO12: 4.003211e+08 | BP12: 3.8985667e+08 | BQ12: 3.9740596e+08
A13: MS | B13: 50 | C13: Mato Grosso do Sul | AC13: 9971231.5 | AD13: 19638571 | AE13: 18091563 | AF13: 22197873 | AG13: 21182185 | AH13: 20494770 | AI13: 20458093 | AJ13: 20084239 | AK13: 20904622 | AL13: 19823006 | AM13: 21374610 | AN13: 25731958 | AO13: 22161090 | AP13: 22475626 | AQ13: 23535734 | AR13: 23875874 | AS13: 24250597 | AT13: 25555211 | AU13: 27432405 | AV13: 31232626 | AW13: 36377027 | AX13: 36117696 | AY13: 34127058 | AZ13: 35926094 | BA13: 38077372 | BB13: 42142149 | BC13: 42846455 | BD13: 47270656 | BE13: 50899075 | BF13: 53037879 | BG13: 55055572 | BH13: 58239959 | BI13: 56977359 | BJ13: 58295005 | BK13: 58986736 | BL13: 62641549 | BM13: 60088107 | BN13: 64712233 | BO13: 66380152 | BP13: 71548266 | BQ13: 75395262
A14: MT | B14: 51 | C14: Mato Grosso | D14: 1115188.5 | E14: 1238644.7 | F14: 1680025.2 | G14: 1641132.8 | H14: 1304243.8 | I14: 1430363.2 | J14: 2100810.9 | K14: 2653116.2 | L14: 3095788.5 | M14: 3020951 | N14: 3094799.6 | O14: 3101402.6 | P14: 4216165.9 | Q14: 3592671.2 | R14: 4347076.9 | S14: 5657998.4 | T14: 6576261.5 | U14: 5364095.3 | V14: 6192660.2 | W14: 6391450.3 | X14: 5525667.4 | Y14: 1711807.5 | Z14: 1876875.2 | AA14: 2161755.6 | AB14: 8527081.5 | AC14: 5399703.4 | AD14: 10901571 | AE14: 13100618 | AF14: 16689868 | AG14: 16623607 | AH14: 18261092 | AI14: 18403355 | AJ14: 17470005 | AK14: 19311881 | AL14: 20041143 | AM14: 23474399 | AN14: 25821782 | AO14: 25235177 | AP14: 25169574 | AQ14: 27202901 | AR14: 27209696 | AS14: 29477998 | AT14: 33569499 | AU14: 34020735 | AV14: 36457362 | AW14: 44453715 | AX14: 51596181 | AY14: 49276282 | AZ14: 41358235 | BA14: 48130349 | BB14: 57248522 | BC14: 57131962 | BD14: 56600955 | BE14: 63843109 | BF14: 68135481 | BG14: 70974582 | BH14: 74678713 | BI14: 73666633 | BJ14: 78587691 | BK14: 77619318 | BL14: 80487074 | BM14: 79853978 | BN14: 94275680 | BO14: 1.0894562e+08 | BP14: 1.0986616e+08 | BQ14: 1.116232e+08
A15: PA | B15: 15 | C15: Pará | D15: 1868118.3 | E15: 2219774.9 | F15: 2178440.8 | G15: 1919519.2 | H15: 2101625.1 | I15: 2319979.4 | J15: 2466861.2 | K15: 2429695.9 | L15: 2667647.5 | M15: 2991430.3 | N15: 3648015.1 | O15: 4886843.1 | P15: 4849223.8 | Q15: 4706352.7 | R15: 5907566 | S15: 6899998 | T15: 6429305.9 | U15: 6527517.1 | V15: 6464268.1 | W15: 7006670.2 | X15: 7730978.6 | Y15: 2425948.4 | Z15: 2723196.1 | AA15: 2899513.6 | AB15: 8593526.3 | AC15: 12952663 | AD15: 27903300 | AE15: 29036764 | AF15: 35610495 | AG15: 37398397 | AH15: 35724237 | AI15: 45217549 | AJ15: 43063777 | AK15: 43060825 | AL15: 37157877 | AM15: 52068287 | AN15: 55413067 | AO15: 37919743 | AP15: 38871711 | AQ15: 38667509 | AR15: 38860134 | AS15: 39345571 | AT15: 43004869 | AU15: 46560031 | AV15: 50309370 | AW15: 50403260 | AX15: 57598290 | AY15: 58289235 | AZ15: 61946795 | BA15: 65621014 | BB15: 70925188 | BC15: 66859356 | BD15: 82684518 | BE15: 91130003 | BF15: 91582804 | BG15: 96442118 | BH15: 91903861 | BI15: 89769844 | BJ15: 87613212 | BK15: 94989539 | BL15: 94486960 | BM15: 1.0022452e+08 | BN15: 1.13952e+08 | BO15: 1.22723e+08 | BP15: 1.0153123e+08 | BQ15: 1.0407473e+08
A16: PB | B16: 25 | C16: Paraíba | D16: 1555581.4 | E16: 2248101.5 | F16: 2625799.2 | G16: 2783864.1 | H16: 3111229.3 | I16: 3017717.5 | J16: 2928403 | K16: 2527442.2 | L16: 2953074.8 | M16: 3188234.9 | N16: 3471627.5 | O16: 3528201.1 | P16: 3450165.8 | Q16: 4846145.3 | R16: 6093338.5 | S16: 6209998.2 | T16: 7678428.2 | U16: 6980530.9 | V16: 7224770.2 | W16: 7587711.1 | X16: 5996464.2 | Y16: 2132095.4 | Z16: 2008038.8 | AA16: 1983483.7 | AB16: 5570288.3 | AC16: 8778658.9 | AD16: 11728044 | AE16: 13689375 | AF16: 15663505 | AG16: 15471506 | AH16: 14567494 | AI16: 15236534 | AJ16: 17689245 | AK16: 17880583 | AL16: 15598357 | AM16: 16730671 | AN16: 18965841 | AO16: 17869416 | AP16: 18727333 | AQ16: 19467281 | AR16: 19690502 | AS16: 20019523 | AT16: 21079071 | AU16: 22628834 | AV16: 24216099 | AW16: 24540320 | AX16: 24350894 | AY16: 25254793 | AZ16: 28072278 | BA16: 28996251 | BB16: 31286787 | BC16: 32776815 | BD16: 33522492 | BE16: 34259250 | BF16: 36338906 | BG16: 36896107 | BH16: 39050201 | BI16: 38501664 | BJ16: 37495134 | BK16: 38181725 | BL16: 37697430 | BM16: 38199275 | BN16: 37094013 | BO16: 36162842 | BP16: 37016932 | BQ16: 39644685
A17: PE | B17: 26 | C17: Pernambuco | D17: 5327333.6 | E17: 6772631 | F17: 7439764.5 | G17: 7565824.3 | H17: 8138646.1 | I17: 8669396.6 | J17: 8164515 | K17: 8294479 | L17: 8990960.2 | M17: 9259657.5 | N17: 10422900 | O17: 11594693 | P17: 12914382 | Q17: 13746278 | R17: 14936110 | S17: 16394395 | T17: 18149012 | U17: 19459002 | V17: 19555769 | W17: 19823750 | X17: 19872580 | Y17: 6659158.7 | Z17: 6633666.8 | AA17: 7224512 | AB17: 22812712 | AC17: 34120825 | AD17: 45426494 | AE17: 49965181 | AF17: 57934820 | AG17: 58696984 | AH17: 55379056 | AI17: 55269134 | AJ17: 55646270 | AK17: 61099349 | AL17: 56067744 | AM17: 56897323 | AN17: 60451052 | AO17: 55894854 | AP17: 58204541 | AQ17: 59409877 | AR17: 59921787 | AS17: 59311317 | AT17: 60858876 | AU17: 63087599 | AV17: 68497295 | AW17: 64632814 | AX17: 69512643 | AY17: 72267054 | AZ17: 74747929 | BA17: 79052867 | BB17: 81928632 | BC17: 86479493 | BD17: 97189760 | BE17: 1.0170143e+08 | BF17: 1.0946488e+08 | BG17: 1.1229405e+08 | BH17: 1.1444568e+08 | BI17: 1.0764444e+08 | BJ17: 1.0616103e+08 | BK17: 1.1113017e+08 | BL17: 1.0912845e+08 | BM17: 1.111677e+08 | BN17: 1.0201076e+08 | BO17: 1.0307487e+08 | BP17: 1.0569588e+08 | BQ17: 1.1058727e+08
A18: PI | B18: 22 | C18: Piauí | D18: 1022848.1 | E18: 1153664.9 | F18: 904441.96 | G18: 889040.48 | H18: 902462.53 | I18: 917525.67 | J18: 1045630.9 | K18: 948139.94 | L18: 957279.28 | M18: 1052904.7 | N18: 1194624.7 | O18: 1315962.1 | P18: 1272446.5 | Q18: 1649553.3 | R18: 1761123.5 | S18: 2144519.4 | T18: 2700308.5 | U18: 2151815.6 | V18: 2553114.3 | W18: 2594176.9 | X18: 2676108 | Y18: 982313.82 | Z18: 966287.17 | AA18: 940719.98 | AB18: 2879274.3 | AC18: 4538401 | AD18: 6769206.8 | AE18: 7513683.2 | AF18: 8747082.7 | AG18: 8446572.6 | AH18: 7898345.1 | AI18: 8179063.5 | AJ18: 9373306.6 | AK18: 9634427.1 | AL18: 8675598.6 | AM18: 9896230.5 | AN18: 10798241 | AO18: 12358499 | AP18: 12687722 | AQ18: 12786207 | AR18: 12747218 | AS18: 12828663 | AT18: 13686306 | AU18: 13501233 | AV18: 13531196 | AW18: 14011771 | AX18: 14535993 | AY18: 15408194 | AZ18: 17998789 | BA18: 17385345 | BB18: 18853050 | BC18: 20542373 | BD18: 22269149 | BE18: 23949131 | BF18: 24492883 | BG18: 24888099 | BH18: 27827881 | BI18: 26848545 | BJ18: 26274247 | BK18: 27760002 | BL18: 29501799 | BM18: 29655893 | BN18: 29758394 | BO18: 29888157 | BP18: 31315823 | BQ18: 33083934
A19: PR | B19: 41 | C19: Paraná | D19: 3473421.5 | E19: 6412110.7 | F19: 7585642.2 | G19: 8486295.5 | H19: 10322688 | I19: 10570733 | J19: 12429798 | K19: 13363327 | L19: 12295330 | M19: 16531588 | N19: 13549770 | O19: 16360610 | P19: 20827606 | Q19: 25302470 | R19: 27568641 | S19: 28427992 | T19: 32330224 | U19: 27798575 | V19: 29279332 | W19: 34520668 | X19: 34442501 | Y19: 11895470 | Z19: 11926605 | AA19: 14611302 | AB19: 42524666 | AC19: 82817537 | AD19: 1.0337917e+08 | AE19: 1.1286654e+08 | AF19: 1.2210436e+08 | AG19: 1.2664425e+08 | AH19: 1.2517174e+08 | AI19: 1.3715697e+08 | AJ19: 1.3278374e+08 | AK19: 1.2420389e+08 | AL19: 1.2325746e+08 | AM19: 1.3060052e+08 | AN19: 1.4247883e+08 | AO19: 1.3857933e+08 | AP19: 1.4028918e+08 | AQ19: 1.4323303e+08 | AR19: 1.47033e+08 | AS19: 1.5111981e+08 | AT19: 1.5605928e+08 | AU19: 1.5938954e+08 | AV19: 1.6762543e+08 | AW19: 1.8322819e+08 | AX19: 1.9077212e+08 | AY19: 1.8334842e+08 | AZ19: 1.854352e+08 | BA19: 2.0909987e+08 | BB19: 2.1604848e+08 | BC19: 2.1324226e+08 | BD19: 225205255 | BE19: 2.3737593e+08 | BF19: 2.4428169e+08 | BG19: 2.6530558e+08 | BH19: 2.5677486e+08 | BI19: 2.5851812e+08 | BJ19: 2.5490452e+08 | BK19: 2.5792223e+08 | BL19: 2.5768294e+08 | BM19: 2.6204285e+08 | BN19: 2.5748727e+08 | BO19: 2.5672524e+08 | BP19: 2.6425723e+08 | BQ19: 2.7431423e+08
A20: RJ | B20: 33 | C20: Rio de Janeiro | D20: 25145015 | E20: 31416767 | F20: 34281268 | G20: 38165879 | H20: 39972085 | I20: 41340986 | J20: 43926045 | K20: 45102975 | L20: 48412863 | M20: 52350030 | N20: 56363837 | O20: 58115732 | P20: 65204968 | Q20: 68032425 | R20: 73194371 | S20: 80315977 | T20: 79172310 | U20: 87411073 | V20: 87457745 | W20: 86130775 | X20: 91681477 | Y20: 30761392 | Z20: 31782815 | AA20: 34737422 | AB20: 1.3067476e+08 | AC20: 1.9346177e+08 | AD20: 2.4653687e+08 | AE20: 2.4211292e+08 | AF20: 2.3765165e+08 | AG20: 2.3636929e+08 | AH20: 2.332877e+08 | AI20: 2.256938e+08 | AJ20: 2.2721843e+08 | AK20: 2.5956366e+08 | AL20: 2.5387444e+08 | AM20: 2.5971017e+08 | AN20: 2.6491707e+08 | AO20: 2.7218524e+08 | AP20: 2.7558726e+08 | AQ20: 2.8213066e+08 | AR20: 2.9400488e+08 | AS20: 3.0329054e+08 | AT20: 3.154896e+08 | AU20: 3.1726108e+08 | AV20: 3.5014388e+08 | AW20: 3.3742005e+08 | AX20: 3.7274161e+08 | AY20: 3.8813092e+08 | AZ20: 4.0379725e+08 | BA20: 4.0969507e+08 | BB20: 4.4014635e+08 | BC20: 4.2464093e+08 | BD20: 449858101 | BE20: 4.7338863e+08 | BF20: 4.9168047e+08 | BG20: 4.9979401e+08 | BH20: 4.9504018e+08 | BI20: 4.5203228e+08 | BJ20: 4.0626035e+08 | BK20: 4.1096776e+08 | BL20: 4.4439083e+08 | BM20: 4.3821741e+08 | BN20: 3.978025e+08 | BO20: 4.4312982e+08 | BP20: 4.959625e+08 | BQ20: 4.7954411e+08
A21: RN | B21: 24 | C21: Rio Grande do Norte | D21: 1001538.7 | E21: 1542511.8 | F21: 1621674.2 | G21: 1762365.6 | H21: 1901764.7 | I21: 2093214.5 | J21: 1973489 | K21: 1577905.9 | L21: 1745497.8 | M21: 1977886.5 | N21: 2325108.5 | O21: 2304712 | P21: 2051107.7 | Q21: 3322405.4 | R21: 3826913.8 | S21: 3946798.9 | T21: 4610730.8 | U21: 4694870.4 | V21: 4644495.2 | W21: 4819221.9 | X21: 4955755.5 | Y21: 1783957.7 | Z21: 1666668.1 | AA21: 1642940.5 | AB21: 4197096 | AC21: 7387324.3 | AD21: 11373842 | AE21: 14883309 | AF21: 15013863 | AG21: 15271015 | AH21: 14447516 | AI21: 16494652 | AJ21: 15030625 | AK21: 16596890 | AL21: 15088639 | AM21: 17130653 | AN21: 17477646 | AO21: 17044638 | AP21: 18277229 | AQ21: 19186801 | AR21: 18849839 | AS21: 19351368 | AT21: 20587521 | AU21: 21575150 | AV21: 25773477 | AW21: 24752657 | AX21: 26660476 | AY21: 28720959 | AZ21: 30836809 | BA21: 33310220 | BB21: 33624650 | BC21: 33547324 | BD21: 36184502 | BE21: 37844773 | BF21: 39694856 | BG21: 40986227 | BH21: 39851397 | BI21: 39262191 | BJ21: 37858387 | BK21: 39350011 | BL21: 39217638 | BM21: 40081934 | BN21: 37772163 | BO21: 37428047 | BP21: 40338413 | BQ21: 41597866
A22: RO | B22: 11 | C22: Rondônia | AB22: 812841.28 | AC22: 1477464.9 | AD22: 4840770 | AE22: 9057871.8 | AF22: 11095005 | AG22: 10659757 | AH22: 10081844 | AI22: 11649084 | AJ22: 10250398 | AK22: 8910151.6 | AL22: 8366131.4 | AM22: 9727616.7 | AN22: 10190951 | AO22: 10814145 | AP22: 11191623 | AQ22: 12126170 | AR22: 12356581 | AS22: 12872720 | AT22: 13423115 | AU22: 13660068 | AV22: 14186599 | AW22: 15693718 | AX22: 17005692 | AY22: 17997345 | AZ22: 17586872 | BA22: 18274213 | BB22: 20112223 | BC22: 21386514 | BD22: 23907887 | BE22: 25457046 | BF22: 25754432 | BG22: 24759074 | BH22: 25103985 | BI22: 25074844 | BJ22: 25033025 | BK22: 26628324 | BL22: 26301802 | BM22: 26459167 | BN22: 27229321 | BO22: 27153569 | BP22: 28719281 | BQ22: 31260127
A23: RR | B23: 14 | C23: Roraima | AB23: 258027.27 | AC23: 407462.28 | AD23: 743825.63 | AE23: 1293287.4 | AF23: 1696203.2 | AG23: 1799853 | AH23: 1873372.2 | AI23: 2302175.4 | AJ23: 2346674.5 | AK23: 1983169.9 | AL23: 1790526.5 | AM23: 1501153.1 | AN23: 1594800 | AO23: 3462416.2 | AP23: 3456583.3 | AQ23: 3469374.2 | AR23: 3468570.1 | AS23: 3741926.4 | AT23: 4010712.9 | AU23: 4240899.2 | AV23: 4544254.6 | AW23: 4319441.1 | AX23: 4362063 | AY23: 4593516.8 | AZ23: 5122536 | BA23: 5319991.5 | BB23: 5633644.9 | BC23: 6149744.6 | BD23: 6639150 | BE23: 6742812 | BF23: 6595367.5 | BG23: 7168607.9 | BH23: 7188047 | BI23: 7024503.2 | BJ23: 6986622.5 | BK23: 7407092.2 | BL23: 7829517.4 | BM23: 8030361 | BN23: 8456217.2 | BO23: 8496891.7 | BP23: 9070124.1 | BQ23: 10272611
A24: RS | B24: 43 | C24: Rio Grande do Sul | D24: 12217352 | E24: 16583933 | F24: 16775940 | G24: 18297171 | H24: 18935230 | I24: 19536668 | J24: 21167261 | K24: 24157321 | L24: 25249339 | M24: 27946257 | N24: 30226410 | O24: 31014026 | P24: 33108930 | Q24: 35087956 | R24: 37897593 | S24: 40571988 | T24: 45005141 | U24: 45198423 | V24: 47096811 | W24: 47508642 | X24: 50300918 | Y24: 15785846 | Z24: 16646469 | AA24: 18495884 | AB24: 67330722 | AC24: 1.076628e+08 | AD24: 1.4219585e+08 | AE24: 1.5019603e+08 | AF24: 1.6690224e+08 | AG24: 1.6875084e+08 | AH24: 1.7154579e+08 | AI24: 1.7904478e+08 | AJ24: 1.7021547e+08 | AK24: 1.6367386e+08 | AL24: 1.8032183e+08 | AM24: 1.9732813e+08 | AN24: 2.0819053e+08 | AO24: 1.719733e+08 | AP24: 1.7116463e+08 | AQ24: 1.7559203e+08 | AR24: 1.7425667e+08 | AS24: 1.7645401e+08 | AT24: 1.8469271e+08 | AU24: 1.9254835e+08 | AV24: 1.8778457e+08 | AW24: 1.9869041e+08 | AX24: 2.0273395e+08 | AY24: 1.9614793e+08 | AZ24: 1.9887222e+08 | BA24: 2.1264483e+08 | BB24: 2.2133784e+08 | BC24: 2.2155761e+08 | BD24: 241249164 | BE24: 2.4470076e+08 | BF24: 2.4596385e+08 | BG24: 2.6436011e+08 | BH24: 2.6395413e+08 | BI24: 2.619675e+08 | BJ24: 2.5932958e+08 | BK24: 2.5900666e+08 | BL24: 2.6779314e+08 | BM24: 2.7108172e+08 | BN24: 2.4852209e+08 | BO24: 2.7134091e+08 | BP24: 2.5523791e+08 | BQ24: 2.6580491e+08
A25: SC | B25: 42 | C25: Santa Catarina | D25: 2692079.3 | E25: 4944278.1 | F25: 5008468.9 | G25: 5118717.9 | H25: 5109833.5 | I25: 5233036.2 | J25: 5665823.2 | K25: 6479189 | L25: 6202555 | M25: 7685220.5 | N25: 8001580.3 | O25: 8109171.9 | P25: 9305951.8 | Q25: 10018474 | R25: 11146351 | S25: 11785197 | T25: 11536012 | U25: 11428303 | V25: 12005069 | W25: 11723355 | X25: 14446027 | Y25: 4744563.4 | Z25: 5142083.6 | AA25: 5813593.3 | AB25: 20930109 | AC25: 35777176 | AD25: 58865731 | AE25: 63021448 | AF25: 72087188 | AG25: 72654517 | AH25: 74538528 | AI25: 91694253 | AJ25: 78136206 | AK25: 73858473 | AL25: 81309926 | AM25: 78437512 | AN25: 85472936 | AO25: 83543747 | AP25: 87003053 | AQ25: 89683950 | AR25: 87083055 | AS25: 88568725 | AT25: 97774525 | AU25: 1.0168332e+08 | AV25: 1.0350175e+08 | AW25: 1.0673128e+08 | AX25: 1.1376486e+08 | AY25: 1.1730266e+08 | AZ25: 1.2267763e+08 | BA25: 1.3128549e+08 | BB25: 1.4134226e+08 | BC25: 1.3997294e+08 | BD25: 153726007 | BE25: 1.6070032e+08 | BF25: 1.6403574e+08 | BG25: 1.7065821e+08 | BH25: 1.7892685e+08 | BI25: 1.7081685e+08 | BJ25: 1.6288108e+08 | BK25: 1.6966671e+08 | BL25: 1.7464295e+08 | BM25: 1.8163198e+08 | BN25: 1.8431693e+08 | BO25: 2.0005519e+08 | BP25: 2.0047857e+08 | BQ25: 2.0990755e+08
A26: SE | B26: 28 | C26: Sergipe | D26: 738723.59 | E26: 955378.75 | F26: 1021144.1 | G26: 1100075.3 | H26: 1019906.3 | I26: 1294304.3 | J26: 1335288.1 | K26: 1337729.1 | L26: 1251489 | M26: 1259549.6 | N26: 1467223.6 | O26: 1586267.8 | P26: 1823206.9 | Q26: 2040972.8 | R26: 2102944.9 | S26: 2409479.3 | T26: 2939111.3 | U26: 2728378.6 | V26: 2618300.2 | W26: 2744564 | X26: 3023010.9 | Y26: 1012870.8 | Z26: 965185.81 | AA26: 972209.9 | AB26: 3377610.2 | AC26: 5035306.3 | AD26: 7005341.9 | AE26: 17529878 | AF26: 17398331 | AG26: 14172549 | AH26: 13258296 | AI26: 11868544 | AJ26: 12031588 | AK26: 13513877 | AL26: 13308664 | AM26: 14482068 | AN26: 13657046 | AO26: 13216639 | AP26: 13739310 | AQ26: 14650059 | AR26: 14413276 | AS26: 14166713 | AT26: 14763285 | AU26: 16726561 | AV26: 19629112 | AW26: 19564382 | AX26: 20608787 | AY26: 20756675 | AZ26: 22120202 | BA26: 23058538 | BB26: 24920895 | BC26: 23535718 | BD26: 26404893 | BE26: 26872831 | BF26: 28098260 | BG26: 28112037 | BH26: 27642675 | BI26: 26441763 | BJ26: 24663229 | BK26: 24912101 | BL26: 24605894 | BM26: 25109640 | BN26: 23963262 | BO26: 24208694 | BP26: 24667690 | BQ26: 24865702
A27: SP | B27: 35 | C27: São Paulo | D27: 37362366 | E27: 54335557 | F27: 61511778 | G27: 67800562 | H27: 73350836 | I27: 77448935 | J27: 86419720 | K27: 87273558 | L27: 97813743 | M27: 1.0430645e+08 | N27: 1.0342724e+08 | O27: 1.1239028e+08 | P27: 1.2661159e+08 | Q27: 1.3746278e+08 | R27: 1.493611e+08 | S27: 1.6477195e+08 | T27: 1.723054e+08 | U27: 1.7914637e+08 | V27: 1.7708835e+08 | W27: 1.8114806e+08 | X27: 2.0046031e+08 | Y27: 62610217 | Z27: 68484981 | AA27: 76393480 | AB27: 3.0896828e+08 | AC27: 5.0678701e+08 | AD27: 6.7465024e+08 | AE27: 6.8885917e+08 | AF27: 7.3227884e+08 | AG27: 8.005468e+08 | AH27: 8.0885187e+08 | AI27: 8.2629803e+08 | AJ27: 7.7468768e+08 | AK27: 7.4530659e+08 | AL27: 7.4622644e+08 | AM27: 7.6954419e+08 | AN27: 7.9755585e+08 | AO27: 9.0779652e+08 | AP27: 8.9624333e+08 | AQ27: 9.3181827e+08 | AR27: 9.0918562e+08 | AS27: 9.1366897e+08 | AT27: 9.5752339e+08 | AU27: 9.6676197e+08 | AV27: 9.8573784e+08 | AW27: 9.848385e+08 | AX27: 1.0090253e+09 | AY27: 1.0688132e+09 | AZ27: 1.1107783e+09 | BA27: 1.1842278e+09 | BB27: 1.2129904e+09 | BC27: 1.2220328e+09 | BD27: 1294695988 | BE27: 1.3263399e+09 | BF27: 1.3333907e+09 | BG27: 1.3645818e+09 | BH27: 1.3707546e+09 | BI27: 1.3303694e+09 | BJ27: 1.2933553e+09 | BK27: 1.2977327e+09 | BL27: 1.2945137e+09 | BM27: 1.3194586e+09 | BN27: 1.2547108e+09 | BO27: 1.2695691e+09 | BP27: 1.3459138e+09 | BQ27: 1.4084581e+09
A28: TO | B28: 17 | C28: Tocantins | AD28: 1286723 | AI28: 3200829.1 | AJ28: 3309159.7 | AK28: 3840800.6 | AL28: 3508743 | AM28: 3901000.3 | AN28: 4433489 | AO28: 6345103.1 | AP28: 6303181 | AQ28: 6667979.6 | AR28: 7174282.5 | AS28: 7189433.1 | AT28: 8288746.2 | AU28: 10102492 | AV28: 10111517 | AW28: 11010299 | AX28: 11206012 | AY28: 11086448 | AZ28: 11660552 | BA28: 12900773 | BB28: 14097770 | BC28: 14842943 | BD28: 16404816 | BE28: 16936786 | BF28: 17690722 | BG28: 18931762 | BH28: 19319348 | BI28: 19840165 | BJ28: 20036905 | BK28: 20871388 | BL28: 20886257 | BM28: 22112888 | BN28: 23034564 | BO28: 24171055 | BP28: 25027373 | BQ28: 26297148

Sheet pib_var_state
A1: Sigla | B1: Codigo | C1: Estado | D1: 1947 | E1: 1948 | F1: 1949 | G1: 1950 | H1: 1951 | I1: 1952 | J1: 1953 | K1: 1954 | L1: 1955 | M1: 1956 | N1: 1957 | O1: 1958 | P1: 1959 | Q1: 1960 | R1: 1961 | S1: 1962 | T1: 1963 | U1: 1964 | V1: 1965 | W1: 1966 | X1: 1970 | Y1: 1975 | Z1: 1980 | AA1: 1985 | AB1: 1986 | AC1: 1987 | AD1: 1988 | AE1: 1989 | AF1: 1990 | AG1: 1991 | AH1: 1992 | AI1: 1993 | AJ1: 1994 | AK1: 1995 | AL1: 1996 | AM1: 1997 | AN1: 1998 | AO1: 1999 | AP1: 2000 | AQ1: 2001 | AR1: 2002 | AS1: 2003 | AT1: 2004 | AU1: 2005 | AV1: 2006 | AW1: 2007 | AX1: 2008 | AY1: 2009 | AZ1: 2010 | BA1: 2011 | BB1: 2012 | BC1: 2013 | BD1: 2014 | BE1: 2015 | BF1: 2016 | BG1: 2017 | BH1: 2018 | BI1: 2019 | BJ1: 2020 | BK1: 2021 | BL1: 2022 | BM1: 2023
A2: AC | B2: 12 | C2: Acre | Y2: -3.9186264 | Z2: 117.23803 | AA2: 18.84484 | AB2: 1.5055948 | AC2: -3.1894579 | AD2: 3.6687267 | AE2: 3.8408117 | AF2: 3.6802716 | AG2: 4.9486247 | AH2: 2.9037204 | AI2: 3.3010053 | AJ2: 1.5660717 | AK2: 4.1316927 | AL2: 2.008661 | AM2: -0.82697314 | AN2: 4.5295861 | AO2: 4.0925989 | AP2: 4.1088419 | AQ2: 3.8004245 | AR2: 4.388001 | AS2: 13.661793 | AT2: 12.044442 | AU2: 13.651628 | AV2: 8.3994697 | AW2: 17.082754 | AX2: 17.443258 | AY2: 15.562033 | AZ2: 12.615518 | BA2: 7.277057 | BB2: 13.280069 | BC2: 13.178288 | BD2: 17.298066 | BE2: 1.2193156 | BF2: 0.96483822 | BG2: 3.771208 | BH2: 7.413903 | BI2: 1.9495897 | BJ2: 5.4149269 | BK2: 29.727839 | BL2: 10.768451 | BM2: 11.045658
A3: AL | B3: 27 | C3: Alagoas | D3: 50.609075 | E3: 5.740759 | F3: 6.0365205 | G3: -0.50903714 | H3: 6.6576038 | I3: -1.1154967 | J3: -0.0005347575 | K3: 2.442904 | L3: 3.4288348 | M3: 15.423137 | N3: 14.560729 | O3: 15.243411 | P3: 5.6102887 | Q3: 7.6557548 | R3: 10.942271 | S3: 6.1099049 | T3: 3.2540565 | U3: 1.3679614 | V3: -0.3695419 | W3: -2.332188 | X3: 28.07457 | Y3: 48.980136 | Z3: 50.183533 | AA3: 37.28732 | AB3: 3.0317588 | AC3: 8.948226 | AD3: -7.4706843 | AE3: 5.5334099 | AF3: 8.0627201 | AG3: 2.5183065 | AH3: 2.9966307 | AI3: -3.8898805 | AJ3: 7.1737698 | AK3: -1.7415161 | AL3: 0.18817654 | AM3: 5.3113137 | AN3: 2.1683782 | AO3: -1.3341022 | AP3: 1.9439824 | AQ3: 1.8336021 | AR3: 0.15503021 | AS3: 9.4235144 | AT3: 11.255336 | AU3: 10.250079 | AV3: 12.342326 | AW3: 14.231098 | AX3: 12.032595 | AY3: 8.6248655 | AZ3: 12.201649 | BA3: 16.674443 | BB3: 9.4546093 | BC3: 7.5962535 | BD3: 9.9040089 | BE3: 13.159775 | BF3: 6.6890588 | BG3: 6.8372995 | BH3: 2.955437 | BI3: 8.3632185 | BJ3: 7.1885209 | BK3: 20.668964 | BL3: -0.26199806 | BM3: 17.909658
A4: AM | B4: 13 | C4: Amazonas | D4: 30.586534 | E4: -9.9407549 | F4: 2.516811 | G4: -4.1576126 | H4: 14.778342 | I4: 4.9702569 | J4: -5.59448 | K4: 5.1298967 | L4: 5.61999 | M4: 32.83055 | N4: 15.00163 | O4: 2.2279958 | P4: 4.7626668 | Q4: 17.318723 | R4: 28.728193 | S4: -18.819003 | T4: -7.1376461 | U4: 4.1611213 | V4: 5.1287207 | W4: -1.2325565 | X4: 40.215676 | Y4: 73.841313 | Z4: 112.48488 | AA4: 46.032088 | AB4: 7.0177972 | AC4: 4.1911603 | AD4: 9.4048099 | AE4: 4.4388472 | AF4: 0.016121929 | AG4: 0.70750126 | AH4: -3.8123801 | AI4: 14.08534 | AJ4: 23.688355 | AK4: 22.58277 | AL4: 12.387915 | AM4: 8.43105 | AN4: 0.61268749 | AO4: -0.2494312 | AP4: 7.8304429 | AQ4: 2.7756058 | AR4: 5.9410001 | AS4: 17.058518 | AT4: 20.217056 | AU4: 9.2959675 | AV4: 17.516723 | AW4: 8.8812288 | AX4: 10.661261 | AY4: 5.0806641 | AZ4: 20.406083 | BA4: 16.192089 | BB4: 2.1323429 | BC4: 14.961417 | BD4: 4.3556379 | BE4: -0.11591274 | BF4: 2.8550882 | BG4: 4.717452 | BH4: 7.367042 | BI4: 8.0630483 | BJ4: 7.2453032 | BK4: 13.370121 | BL4: 10.346932 | BM4: 11.474754
A5: AP | B5: 16 | C5: Amapá | Y5: -14.844355 | Z5: 96.089818 | AA5: 57.231258 | AB5: 6.6636335 | AC5: 1.1855704 | AD5: 1.3974242 | AE5: 4.7596051 | AF5: 1.3680245 | AG5: 5.3847758 | AH5: 8.578 | AI5: 10.134043 | AJ5: 5.0800518 | AK5: 4.5228029 | AL5: 5.2246804 | AM5: 5.1977135 | AN5: -0.35583888 | AO5: 2.1797073 | AP5: 5.2410701 | AQ5: 6.18742 | AR5: 6.9485811 | AS5: 7.5583383 | AT5: 12.057471 | AU5: 12.593536 | AV5: 22.627014 | AW5: 13.855816 | AX5: 15.598942 | AY5: 7.7728187 | AZ5: 9.97428 | BA5: 14.220225 | BB5: 18.297357 | BC5: 14.667481 | BD5: 4.9892169 | BE5: 3.4402928 | BF5: 3.4689549 | BG5: 7.9470246 | BH5: 8.4827981 | BI5: 4.176513 | BJ5: 5.5579405 | BK5: 8.8295297 | BL5: 17.484911 | BM5: 18.657469
A6: BA | B6: 29 | C6: Bahia | D6: 34.624221 | E6: 2.999761 | F6: 0.1528944 | G6: 6.4186585 | H6: -0.12425443 | I6: 2.3590244 | J6: 9.6648739 | K6: 19.122203 | L6: 3.3293366 | M6: 2.617028 | N6: 10.801738 | O6: 15.706985 | P6: 13.519628 | Q6: 10.975654 | R6: -4.2868322 | S6: 5.2458512 | T6: -5.8621362 | U6: 17.432935 | V6: 7.5872626 | W6: 6.1222428 | X6: 28.51332 | Y6: 57.096491 | Z6: 66.303374 | AA6: 31.195654 | AB6: 7.1230462 | AC6: 3.3885474 | AD6: 17.987132 | AE6: -7.0645721 | AF6: 6.4156101 | AG6: 3.0687748 | AH6: 3.0687748 | AI6: 10.68046 | AJ6: 6.8603406 | AK6: 6.8603406 | AL6: 1.656786 | AM6: 6.4649171 | AN6: 0.4597258 | AO6: 0.61745013 | AP6: 4.0501512 | AQ6: 0.43200755 | AR6: 1.5107322 | AS6: 14.158446 | AT6: 16.014323 | AU6: 13.29389 | AV6: 7.9915829 | AW6: 14.663921 | AX6: 11.285082 | AY6: 13.376647 | AZ6: 11.944882 | BA6: 7.8897201 | BB6: 9.5855 | BC6: 12.198847 | BD6: 9.3171713 | BE6: 9.4287175 | BF6: 5.5889136 | BG6: 3.8591481 | BH6: 6.5180055 | BI6: 2.4458406 | BJ6: 4.1195909 | BK6: 15.490932 | BL6: 14.187811 | BM6: 7.0387398
A7: CE | B7: 23 | C7: Ceará | D7: 23.481205 | E7: 7.7844061 | F7: 9.6597403 | G7: 20.625414 | H7: -20.480816 | I7: 19.176336 | J7: -10.758644 | K7: 6.7574108 | L7: 10.308282 | M7: 18.311983 | N7: 10.651639 | O7: -29.051984 | P7: 77.329528 | Q7: 16.484248 | R7: 4.5871859 | S7: 19.845317 | T7: -1.7935515 | U7: 9.6801533 | V7: 3.660357 | W7: -4.7396641 | X7: 0.18370147 | Y7: 44.818204 | Z7: 69.511535 | AA7: 18.732145 | AB7: 12.000948 | AC7: 0.17151657 | AD7: -4.7570821 | AE7: -5.2846182 | AF7: 11.608015 | AG7: 5.8481856 | AH7: 5.8481856 | AI7: 6.1433425 | AJ7: 11.470546 | AK7: 11.470546 | AL7: 3.4313307 | AM7: 2.187971 | AN7: -0.74964768 | AO7: 0.65124892 | AP7: 4.541688 | AQ7: -1.400313 | AR7: 3.6413454 | AS7: 13.818727 | AT7: 12.859376 | AU7: 11.299948 | AV7: 13.251178 | AW7: 9.2868778 | AX7: 18.884418 | AY7: 11.229528 | AZ7: 18.060043 | BA7: 13.057742 | BB7: 8.1140061 | BC7: 12.439245 | BD7: 15.607533 | BE7: 3.6296824 | BF7: 5.9654605 | BG7: 6.862332 | BH7: 5.3963009 | BI7: 4.9206631 | BJ7: 2.0413892 | BK7: 16.757238 | BL7: 9.6035566 | BM7: 8.7259008
A8: DF | B8: 53 | C8: Distrito Federal | Y8: 75.425197 | Z8: 107.02126 | AA8: -27.512616 | AB8: 6.5466305 | AC8: 2.2913791 | AD8: 3.8583785 | AE8: 2.3755305 | AF8: 3.3247776 | AG8: 1.3825516 | AH8: 1.2778018 | AI8: 4.5613999 | AJ8: 2.8753346 | AK8: 3.523398 | AL8: 2.9749545 | AM8: 3.7944909 | AN8: 2.3042977 | AO8: 3.0590586 | AP8: 3.3080757 | AQ8: 3.2688259 | AR8: 4.0969578 | AS8: 8.4484938 | AT8: 14.746754 | AU8: 12.90493 | AV8: 11.789791 | AW8: 10.326541 | AX8: 18.088686 | AY8: 12.714644 | AZ8: 15.966658 | BA8: 7.2099301 | BB8: 6.1670741 | BC8: 7.1939634 | BD8: 12.236788 | BE8: 9.2086382 | BF8: 9.2421119 | BG8: 3.8983622 | BH8: 4.1250667 | BI8: 7.3764666 | BJ8: -2.8384458 | BK8: 7.93555 | BL8: 14.583268 | BM8: 11.216763
A9: ES | B9: 32 | C9: Espírito Santo | D9: 35.470118 | E9: 5.1244404 | F9: 36.24664 | G9: -0.64468732 | H9: 34.672512 | I9: -23.852054 | J9: 11.20133 | K9: 4.3874074 | L9: 5.6905193 | M9: -0.43190909 | N9: 12.337329 | O9: -0.61262967 | P9: 8.1990583 | Q9: 7.7715535 | R9: -8.0053247 | S9: 13.071673 | T9: 3.0595066 | U9: 40.12908 | V9: -10.494762 | W9: 8.1118073 | X9: 40.830009 | Y9: 42.595215 | Z9: 100.79355 | AA9: 24.15359 | AB9: 3.2764515 | AC9: -1.5452711 | AD9: 3.7091211 | AE9: 2.8350902 | AF9: -3.0072877 | AG9: 6.7921206 | AH9: 2.7369292 | AI9: 2.8476188 | AJ9: 6.6973479 | AK9: 0.42778993 | AL9: 6.2345884 | AM9: 0.46913399 | AN9: 3.3875358 | AO9: 0.95651327 | AP9: 8.9587316 | AQ9: 0.33016676 | AR9: 7.0795656 | AS9: 16.52597 | AT9: 26.058899 | AU9: 18.342477 | AV9: 13.703104 | AW9: 13.456802 | AX9: 18.847784 | AY9: -3.989112 | AZ9: 23.253399 | BA9: 24.224438 | BB9: 10.261131 | BC9: 0.36265631 | BD9: 9.8141105 | BE9: -6.5363829 | BF9: -9.2231684 | BG9: 3.7848678 | BH9: 20.82904 | BI9: 0.23758566 | BJ9: 0.80113745 | BK9: 34.591545 | BL9: -2.0328357 | BM9: 14.944592
A10: GO | B10: 52 | C10: Goiás | D10: 10.700087 | E10: 11.907412 | F10: 9.4994966 | G10: 29.184361 | H10: 23.018298 | I10: -17.081646 | J10: 42.709974 | K10: -0.83341142 | L10: 20.253861 | M10: -0.60260821 | N10: -1.11254 | O10: 19.909178 | P10: 18.999378 | Q10: 0.72068215 | R10: 21.136306 | S10: 26.670126 | T10: 1.1379821 | U10: 10.120923 | V10: -0.3414495 | W10: 0.99200767 | X10: 13.67423 | Y10: 62.329001 | Z10: 58.966175 | AA10: 12.286384 | AB10: 6.5831693 | AC10: 2.4601029 | AD10: 6.3203011 | AE10: 0.13039825 | AF10: 0.011146086 | AG10: 2.3821251 | AH10: 1.8516534 | AI10: 6.4259512 | AJ10: 2.7085734 | AK10: 1.8365151 | AL10: 2.6399014 | AM10: 4.8318156 | AN10: 1.192742 | AO10: 1.7472526 | AP10: 5.0097392 | AQ10: 3.3378928 | AR10: 5.3172474 | AS10: 17.935899 | AT10: 12.17336 | AU10: 5.4033109 | AV10: 13.942772 | AW10: 16.350467 | AX10: 15.413679 | AY10: 12.677127 | AZ10: 14.972546 | BA10: 13.605505 | BB10: 14.395364 | BC10: 9.0390218 | BD10: 9.064856 | BE10: 5.2220194 | BF10: 4.6806654 | BG10: 5.6055893 | BH10: 1.9450149 | BI10: 6.6387232 | BJ10: 7.4056814 | BK10: 20.301857 | BL10: 18.15772 | BM10: 5.7004443
A11: MA | B11: 21 | C11: Maranhão | D11: -9.8738823 | E11: 15.310139 | F11: -8.9144585 | G11: 19.112606 | H11: 8.866286 | I11: 11.458832 | J11: 10.5961 | K11: 6.0276012 | L11: 4.5601078 | M11: 3.0559436 | N11: 8.3734339 | O11: 20.381944 | P11: 25.526681 | Q11: 13.921731 | R11: 5.4372134 | S11: 19.915951 | T11: -8.7058053 | U11: 2.2784178 | V11: 2.4688058 | W11: 5.8472815 | X11: 6.1313669 | Y11: 43.112976 | Z11: 64.788515 | AA11: -6.8518311 | AB11: 20.073188 | AC11: 2.8849526 | AD11: 9.0274987 | AE11: 0.6932888 | AF11: -1.1733811 | AG11: 4.2014284 | AH11: -2.6702868 | AI11: 6.1097456 | AJ11: 2.2717518 | AK11: 1.5461132 | AL11: 4.3008773 | AM11: 2.884993 | AN11: -4.9195212 | AO11: 2.8511664 | AP11: 4.3687528 | AQ11: 1.7547721 | AR11: 2.8153848 | AS11: 22.474858 | AT11: 13.455599 | AU11: 13.454419 | AV11: 18.34925 | AW11: 3.4338638 | AX11: 23.434211 | AY11: 8.0727 | AZ11: 12.965283 | BA11: 12.597599 | BB11: 16.00692 | BC11: 11.910602 | BD11: 13.512377 | BE11: 2.1263962 | BF11: 8.7084517 | BG11: 4.961572 | BH11: 9.6453798 | BI11: -0.8551256 | BJ11: 9.8377133 | BK11: 16.896222 | BL11: 11.848568 | BM11: 6.7516322
A12: MG | B12: 31 | C12: Minas Gerais | D12: 59.078928 | E12: 11.129464 | F12: 0.26313399 | G12: 4.3469277 | H12: 7.2762269 | I12: 2.5040061 | J12: 11.439007 | K12: 5.6185632 | L12: 3.9117313 | M12: 4.1054903 | N12: 9.1892357 | O12: 5.2683486 | P12: 9.2105779 | Q12: 9.9572422 | R12: 7.2033311 | S12: 12.159824 | T12: -10.142668 | U12: 15.373557 | V12: 1.6680904 | W12: 8.7056239 | X12: 9.6013448 | Y12: 64.64698 | Z12: 58.583442 | AA12: 8.3919411 | AB12: 0.88543727 | AC12: 11.842018 | AD12: -1.2337668 | AE12: 1.4503019 | AF12: -2.150698 | AG12: 2.5253376 | AH12: -2.0939579 | AI12: 4.2297129 | AJ12: 5.5474819 | AK12: 3.1649824 | AL12: 3.691622 | AM12: 2.9954155 | AN12: -0.26576029 | AO12: 0.081581072 | AP12: 5.1114479 | AQ12: -0.11598956 | AR12: 3.7311496 | AS12: 16.214923 | AT12: 19.19829 | AU12: 9.5964464 | AV12: 12.897929 | AW12: 13.023489 | AX12: 15.914935 | AY12: 3.1715676 | AZ12: 22.153743 | BA12: 13.955568 | BB12: 10.536251 | BC12: 10.337745 | BD12: 5.866556 | BE12: 0.52207735 | BF12: 4.9061667 | BG12: 5.7937721 | BH12: 6.6797204 | BI12: 6.0169652 | BJ12: 4.7422499 | BK12: 25.602029 | BL12: 5.7296928 | BM12: 7.1958392
A13: MS | B13: 50 | C13: Mato Grosso do Sul | Z13: 97.19538 | AA13: -7.9465401 | AB13: 2.4981958 | AC13: 8.0603021 | AD13: 4.4773193 | AE13: 6.6409666 | AF13: 0.55631549 | AG13: 5.3778139 | AH13: 2.0229986 | AI13: 7.968057 | AJ13: 3.3882723 | AK13: 4.9600393 | AL13: 2.1762207 | AM13: 4.5429915 | AN13: 2.7784103 | AO13: 0.92246957 | AP13: 2.4220127 | AQ13: 6.3045442 | AR13: 2.9437486 | AS13: 32.883227 | AT13: 6.9838985 | AU13: 1.5101204 | AV13: 12.402967 | AW13: 12.812677 | AX13: 20.390713 | AY13: 9.1069744 | AZ13: 19.618818 | BA13: 16.632953 | BB13: 12.478949 | BC13: 11.594306 | BD13: 14.08451 | BE13: 5.2342179 | BF13: 10.603586 | BG13: 4.9015529 | BH13: 10.967945 | BI13: -0.024208851 | BJ13: 14.666172 | BK13: 15.963796 | BL13: 17.020338 | BM13: 10.8137
A14: MT | B14: 51 | C14: Mato Grosso | D14: 10.728476 | E14: 35.826089 | F14: -2.294231 | G14: -20.586465 | H14: 9.566908 | I14: 47.080456 | J14: 26.216543 | K14: 16.501928 | L14: -2.1624211 | M14: 2.2975685 | N14: 0.11507498 | O14: 36.206581 | P14: -14.816108 | Q14: 20.820107 | R14: 30.396668 | S14: 16.017703 | T14: -18.282877 | U14: 15.763345 | V14: 2.9728698 | W14: -13.789181 | X14: 54.592166 | Y14: -36.631578 | Z14: 101.73927 | AA14: 20.183568 | AB14: 12.308627 | AC14: 7.1744279 | AD14: 9.7863495 | AE14: 13.820405 | AF14: 1.4944242 | AG14: 7.473219 | AH14: 11.126824 | AI14: 7.1259202 | AJ14: 11.888828 | AK14: 1.9510885 | AL14: 2.8862213 | AM14: 5.4222754 | AN14: 6.5417499 | AO14: 7.6581603 | AP14: 7.6362241 | AQ14: 6.743159 | AR14: 9.4212633 | AS14: 39.115105 | AT14: 25.064796 | AU14: 2.6008373 | AV14: -10.382942 | AW14: 23.867667 | AX14: 29.386376 | AY14: 7.0949884 | AZ14: 7.4156094 | BA14: 22.178075 | BB14: 15.200481 | BC14: 11.984115 | BD14: 13.47518 | BE14: 6.1083897 | BF14: 15.325111 | BG14: 2.3939255 | BH14: 8.354196 | BI14: 3.4044513 | BJ14: 25.70153 | BK14: 30.64135 | BL14: 9.4850145 | BM14: 6.8412609
A15: PA | B15: 15 | C15: Pará | D15: 18.917897 | E15: -1.7355299 | F15: -11.891842 | G15: 9.6177228 | H15: 9.8157043 | I15: 6.6726916 | J15: -1.2985758 | K15: 9.4312759 | L15: 12.200685 | M15: 22.218392 | N15: 33.84115 | O15: -0.78139577 | P15: -2.9925813 | Q15: 25.841457 | R15: 16.596889 | S15: -6.7591167 | T15: 1.364985 | U15: -1.2495981 | V15: 8.7737361 | W15: 10.29731 | X15: 11.143508 | Y15: 50.88993 | Z15: 115.21127 | AA15: 4.0947869 | AB15: 16.636233 | AC15: 6.3214519 | AD15: 4.876458 | AE15: 3.9263688 | AF15: 4.97954 | AG15: -2.1320788 | AH15: 3.4265163 | AI15: 7.0244457 | AJ15: -1.5975612 | AK15: 0.031741404 | AL15: 0.27649984 | AM15: 2.9552757 | AN15: 2.2579816 | AO15: 1.812417 | AP15: 4.7029644 | AQ15: 3.4979548 | AR15: 3.6376466 | AS15: 14.303943 | AT15: 23.133594 | AU15: 8.7199605 | AV15: 13.474196 | AW15: 12.752203 | AX15: 17.571169 | AY15: 1.1616685 | AZ15: 34.086417 | BA15: 19.382369 | BB15: 8.4794677 | BC15: 13.208675 | BD15: 2.7717898 | BE15: 5.0684776 | BF15: 5.5065212 | BG15: 12.39968 | BH15: 3.9406708 | BI15: 10.553098 | BJ15: 21.055755 | BK15: 21.751566 | BL15: -10.179764 | BM15: 7.7938896
A16: PB | B16: 25 | C16: Paraíba | D16: 44.654025 | E16: 17.426383 | F16: 5.7104506 | G16: 11.560842 | H16: -2.8045695 | I16: -3.3234481 | J16: -13.574638 | K16: 16.95747 | L16: 8.0619768 | M16: 8.8239658 | N16: 1.4796387 | O16: -2.1575138 | P16: 39.816245 | Q16: 26.52436 | R16: 1.5711879 | S16: 23.732287 | T16: -8.9577452 | U16: 3.7775531 | V16: 4.5582273 | W16: -20.783959 | X16: -7.1516375 | Y16: 57.439046 | Z16: 33.83371 | AA16: 16.587222 | AB16: 7.7317013 | AC16: 0.35360491 | AD16: 2.8351616 | AE16: 2.3856878 | AF16: 2.8605882 | AG16: 2.6033473 | AH16: -2.2004935 | AI16: -3.1365456 | AJ16: 12.962608 | AK16: 4.0093112 | AL16: 2.6448107 | AM16: 3.0643319 | AN16: -2.2899913 | AO16: 2.7826457 | AP16: 4.3728001 | AQ16: 0.82790606 | AR16: 4.7671405 | AS16: 15.618543 | AT16: 6.9203253 | AU16: 11.419045 | AV16: 18.686266 | AW16: 9.9423813 | AX16: 17.371431 | AY16: 12.424269 | AZ16: 10.889983 | BA16: 10.699219 | BB16: 14.495654 | BC16: 9.1529798 | BD16: 14.143092 | BE16: 6.0551945 | BF16: 5.2775049 | BG16: 5.5697609 | BH16: 3.1681429 | BI16: 5.6117403 | BJ16: 3.3918123 | BK16: 10.212106 | BL16: 11.1318 | BM16: 12.624549
A17: PE | B17: 26 | C17: Pernambuco | D17: 27.0646 | E17: 10.032186 | F17: 1.5018244 | G17: 7.5214179 | H17: 6.539897 | I17: -5.7441866 | J17: 1.5413394 | K17: 8.3911144 | L17: 3.0630035 | M17: 12.33577 | N17: 11.25721 | O17: 11.572004 | P17: 6.5628386 | Q17: 8.5352867 | R17: 9.7382041 | S17: 10.712642 | T17: 6.9257755 | U17: 0.80031794 | V17: 1.3828653 | W17: 0.25159953 | X17: 14.568575 | Y17: 49.376317 | Z17: 33.48723 | AA17: 9.9912332 | AB17: 10.189992 | AC17: 15.520917 | AD17: -1.7321515 | AE17: -5.5458654 | AF17: 14.765666 | AG17: 8.1266843 | AH17: 8.1266843 | AI17: -5.0977201 | AJ17: 2.8541048 | AK17: 2.8541048 | AL17: 0.29314019 | AM17: 3.1292617 | AN17: -0.38934005 | AO17: 0.652829 | AP17: 4.3287522 | AQ17: 1.6397355 | AR17: 4.1113568 | AS17: 7.6542338 | AT17: 15.887427 | AU17: 11.688144 | AV17: 10.439757 | AW17: 12.569154 | AX17: 12.735671 | AY17: 13.274387 | AZ17: 21.851295 | BA17: 13.346878 | BB17: 16.183035 | BC17: 10.283075 | BD17: 9.9131215 | BE17: 1.1737714 | BF17: 6.6138637 | BG17: 8.5239878 | BH17: 2.6113579 | BI17: 6.1718707 | BJ17: -2.2976919 | BK17: 14.229262 | BL17: 11.328334 | BM17: 10.026075
